<?xml version="1.0"?>
<robot name="vector" xmlns:xacro="http://www.ros.org/wiki/xacro">

    <include filename="$(find vector_description)/urdf/common/inertia.xacro"/>
    <include filename="$(find vector_description)/urdf/components/drop_sensor.urdf.xacro"/>
    <include filename="$(find vector_description)/urdf/components/imu.urdf.xacro"/>
    <include filename="$(find vector_description)/urdf/components/camera.urdf.xacro"/>
    <include filename="$(find vector_description)/urdf/components/wheel.urdf.xacro"/>
    <include filename="$(find vector_description)/urdf/components/belt.urdf.xacro"/>

    <link name="base_footprint"/>

    <joint name="base_footprint_joint" type="fixed">
        <origin rpy="0 0 0" xyz="0 0 0.027"/>
        <parent link="base_footprint"/>
        <child link="base_link"/>
    </joint>

    <link name="base_link">
        <inertial>
            <origin rpy="0 0 0" xyz="0.0075 0.0 -0.01"/>
            <geometry>
                <box size="0.073 0.043 0.061"/>
            </geometry>
            <mass value="0.16"/>
            <box_inertia m="0.16" x="0.073" y="0.043" z="0.061"/>
        </inertial>
        <visual>
            <geometry>
                <mesh filename="package://vector_description/meshes/vector_body.dae"/>
            </geometry>
        </visual>
        <collision>
            <origin rpy="0 0 0" xyz="0.0075 0.0 -0.01"/>
            <geometry>
                <box size="0.07 0.03 0.01"/>
            </geometry>
        </collision>
    </link>

    <gazebo reference="base_link">
        <selfCollide>
            true
        </selfCollide>
        <mu1 value="200.0"/>
        <mu2 value="100.0"/>
        <kp value="10000000.0"/>
        <kd value="1.0"/>
    </gazebo>

    <joint name="base_to_head" type="revolute">
        <parent link="base_link"/>
        <child link="head"/>
        <origin xyz="0.0174507 0 0.022003"/>
        <limit lower="-0.52" upper="0.17" effort="100" velocity="10"/>
        <!-- Dampning break the model, keep it 0.0 -->
        <dynamics damping="0.0" friction="0.1"/>
        <axis xyz="0 1 0"/>
    </joint>

    <!-- Head -->
    <link name="head">
        <inertial>
            <geometry>
                <sphere radius="0.02"/>
            </geometry>
            <mass value="0.03"/>
            <sphere_inertia m="0.03" r="0.02"/>
        </inertial>
        <visual>
            <geometry>
                <mesh filename="package://vector_description/meshes/vector_head.dae"/>
            </geometry>
        </visual>
        <collision>
            <geometry>
                <sphere radius="0.02"/>
            </geometry>
        </collision>
    </link>

    <gazebo reference="head">
        <mu1 value="200.0"/>
        <mu2 value="100.0"/>
        <kp value="10000000.0"/>
        <kd value="1.0"/>
    </gazebo>

    <joint name="base_to_lift" type="revolute">
        <parent link="base_link"/>
        <child link="full_lift"/>
        <origin xyz="-0.005 0 0.013"/>
        <limit lower="-0.8" upper="0" effort="5" velocity="10"/>
        <dynamics damping="0.0" friction="0.1"/>
        <axis xyz="0 1 0"/>
    </joint>

    <!-- lifter -->
    <link name="full_lift">
        <inertial>
            <origin rpy="0 0 0" xyz="0.062 0.0 -0.015"/>
            <geometry>
                <box size="0.0075 0.05 0.025"/>
            </geometry>
            <mass value="0.05"/>
            <box_inertia m="0.05" x="0.0075" y="0.05" z="0.025"/>
        </inertial>
        <visual>
            <geometry>
                <mesh filename="package://vector_description/meshes/vector_lift.dae"/>
            </geometry>
        </visual>
        <collision>
            <origin rpy="0 0 0" xyz="0.062 0.0 -0.015"/>
            <geometry>
                <box size="0.0075 0.05 0.025"/>
            </geometry>
        </collision>
    </link>

    <gazebo reference="full_lift">
        <mu1 value="200.0"/>
        <mu2 value="100.0"/>
        <kp value="10000000.0"/>
        <kd value="1.0"/>
    </gazebo>

    <wheel link_name="front_left_wheel" radius="0.01314" filename="package://vector_description/meshes/flw2.dae">
        <origin xyz="0.03 0.024 -0.012"/>
    </wheel>
    <wheel link_name="front_right_wheel" radius="0.01314" filename="package://vector_description/meshes/flw2.dae">
        <origin xyz="0.03 -0.024 -0.012" rpy="0 0 ${-pi}"/>
    </wheel>
    <wheel link_name="rear_left_wheel" radius="0.008995" filename="package://vector_description/meshes/rlw2.dae">
        <origin xyz="-0.017 0.024 -0.0151707"/>
    </wheel>
    <wheel link_name="rear_right_wheel" radius="0.008995" filename="package://vector_description/meshes/rlw2.dae">
        <origin xyz="-0.017 -0.024 -0.0151707" rpy="0 0 ${-pi}"/>
    </wheel>

    <belt link_name="left_belt" filename="package://vector_description/meshes/cozmo_belt.dae">
        <origin xyz="0.00945088 0.024 -0.0133211"/>
    </belt>
    <belt link_name="right_belt" filename="package://vector_description/meshes/cozmo_belt.dae">
        <origin xyz="0.00945088 -0.024 -0.0133211"/>
    </belt>

    <!-- sensors -->
    <drop_sensor link_name="drop_front_left">
        <origin xyz="0.0351028 0.01 -0.0213898" rpy="0 1.57 0"/>
    </drop_sensor>
    <drop_sensor link_name="drop_front_right">
        <origin xyz="0.0351028 -0.01 -0.0213898" rpy="0 1.57 0"/>
    </drop_sensor>
    <drop_sensor link_name="drop_rear_left">
        <origin xyz="-0.02 0.01 -0.0213898" rpy="0 1.57 0"/>
    </drop_sensor>
    <drop_sensor link_name="drop_rear_right">
        <origin xyz="-0.02 -0.01 -0.0213898" rpy="0 1.57 0"/>
    </drop_sensor>
    <imu_sensor link_name="imu"/>
    <camera link_name="camera">
        <origin xyz="0.020813 0 -0.0071471" rpy="0 0 0"/>
    </camera>

    <gazebo reference="rear_right_wheel">
        <mu1>0.5</mu1>
        <mu2>0.5</mu2>
    </gazebo>
    <gazebo reference="rear_left_wheel">
        <mu1>0.5</mu1>
        <mu2>0.5</mu2>
    </gazebo>
    <gazebo reference="front_right_wheel">
        <mu1>100000</mu1>
        <mu2>100000</mu2>
    </gazebo>
    <gazebo reference="front_left_wheel">
        <mu1>100000</mu1>
        <mu2>100000</mu2>
    </gazebo>

    <!-- Transmissions for joints -->
    <transmission name="base_to_head_trans">
        <type>
            transmission_interface/SimpleTransmission
        </type>
        <joint name="base_to_head">
            <hardwareInterface>
                hardware_interface/EffortJointInterface
            </hardwareInterface>
        </joint>
        <actuator name="base_to_headMotor">
            <hardwareInterface>
                hardware_interface/EffortJointInterface
            </hardwareInterface>
            <mechanicalReduction>
                1
            </mechanicalReduction>
        </actuator>
    </transmission>
    <transmission name="base_to_lift_trans">
        <type>
            transmission_interface/SimpleTransmission
        </type>
        <joint name="base_to_lift">
            <hardwareInterface>
                hardware_interface/EffortJointInterface
            </hardwareInterface>
        </joint>
        <actuator name="base_to_liftMotor">
            <hardwareInterface>
                hardware_interface/EffortJointInterface
            </hardwareInterface>
            <mechanicalReduction>
                1
            </mechanicalReduction>
        </actuator>
    </transmission>

    <!-- components -->
    <include filename="$(find vector_description)/urdf/vector.gazebo"/>
</robot>
