<?xml version="1.0"?>
<robot name="vector" xmlns:xacro="http://www.ros.org/wiki/xacro">

    <xacro:include filename="$(find vector_description)/urdf/common/inertia.xacro"/>
    <xacro:include filename="$(find vector_description)/urdf/components/drop_sensor.urdf.xacro"/>
    <xacro:include filename="$(find vector_description)/urdf/components/imu.urdf.xacro"/>
    <xacro:include filename="$(find vector_description)/urdf/components/camera.urdf.xacro"/>
    <xacro:include filename="$(find vector_description)/urdf/components/wheel.urdf.xacro"/>

    <!-- LINKS ===========================  -->

    <!--chassis-->

    <link name="dummy"/>

    <link name="base_link">
        <xacro:box_inertia m="0.06" x="0.073" y="0.043" z="0.061"/>
        <visual>
            <geometry>
                <mesh filename="package://vector_description/meshes/vector_body.dae"/>
            </geometry>
        </visual>
        <collision>
            <geometry>
                <mesh filename="package://vector_description/meshes/vector_body.dae"/>
            </geometry>
        </collision>
    </link>

    <xacro:wheel link_name="front_left_wheel" radius="0.01314" filename="package://vector_description/meshes/flw2.dae">
        <origin xyz="0.03 0.024 -0.012"/>
    </xacro:wheel>

    <xacro:wheel link_name="front_right_wheel" radius="0.01314" filename="package://vector_description/meshes/flw2.dae">
        <origin xyz="0.03 -0.024 -0.012" rpy="0 0 ${-pi}"/>
    </xacro:wheel>

    <xacro:wheel link_name="rear_left_wheel" radius="0.008995" filename="package://vector_description/meshes/rlw2.dae">
        <origin xyz="-0.017 0.024 -0.0151707"/>
    </xacro:wheel>

    <xacro:wheel link_name="rear_right_wheel" radius="0.008995" filename="package://vector_description/meshes/rlw2.dae">
        <origin xyz="-0.017 -0.024 -0.0151707" rpy="0 0 ${-pi}"/>
    </xacro:wheel>

    <!-- Head -->
    <link name="head">
        <xacro:box_inertia m="0.01" x="0.036" y="0.038" z="0.041"/>
        <visual>
            <geometry>
                <mesh filename="package://vector_description/meshes/vector_head.dae"/>
            </geometry>
        </visual>
        <collision>
            <geometry>
                <mesh filename="package://vector_description/meshes/vector_head.dae"/>
            </geometry>
        </collision>
    </link>

    <!-- lifter -->
    <link name="full_lift">
        <xacro:box_inertia m="0.01" x="0.081" y="0.058" z="0.050"/>
        <visual>
            <geometry>
                <mesh filename="package://vector_description/meshes/vector_lift.dae"/>
            </geometry>
        </visual>
        <collision>
            <geometry>
                <mesh filename="package://vector_description/meshes/vector_lift.dae"/>
            </geometry>
        </collision>
    </link>

    <!-- Belts -->
    <link name="left_belt">
        <inertial>
            <mass value="0.0001"/>
            <inertia ixx="0.000001" ixy="0" ixz="0" iyy="0.000001" iyz="0" izz="0.0000001"/>
        </inertial>
        <visual>
            <geometry>
                <mesh filename="package://vector_description/meshes/cozmo_belt.dae"/>
            </geometry>
        </visual>
    </link>

    <link name="right_belt">
        <inertial>
            <mass value="0.0001"/>
            <inertia ixx="0.000001" ixy="0" ixz="0" iyy="0.000001" iyz="0" izz="0.0000001"/>
        </inertial>
        <visual>
            <geometry>
                <mesh filename="package://vector_description/meshes/cozmo_belt.dae"/>
            </geometry>
        </visual>
    </link>

    <!-- sensors -->

    <xacro:drop_sensor link_name="drop_front_left">
        <origin xyz="0.0351028 0.01 -0.0213898" rpy="0 1.57 0"/>
    </xacro:drop_sensor>

    <xacro:drop_sensor link_name="drop_front_right">
        <origin xyz="0.0351028 -0.01 -0.0213898" rpy="0 1.57 0"/>
    </xacro:drop_sensor>

    <xacro:drop_sensor link_name="drop_rear_left">
        <origin xyz="-0.02 0.01 -0.0213898" rpy="0 1.57 0"/>
    </xacro:drop_sensor>

    <xacro:drop_sensor link_name="drop_rear_right">
        <origin xyz="-0.02 -0.01 -0.0213898" rpy="0 1.57 0"/>
    </xacro:drop_sensor>

    <xacro:imu_sensor link_name="imu"/>

    <xacro:camera link_name="camera">
        <origin xyz="0.020813 0 -0.0071471" rpy="0 0 0"/>
    </xacro:camera>

    <!-- JOINTS ====================================-->
    <joint name="dummy_joint" type="fixed">
        <parent link="dummy"/>
        <child link="base_link"/>
    </joint>

    <joint name="base_to_head" type="revolute">
        <parent link="base_link"/>
        <child link="head"/>
        <origin xyz="0.0174507 0 0.022003"/>
        <limit lower="-0.52" upper="0.17" effort="100" velocity="10"/>
        <!-- Dampning break the model, keep it 0.0 -->
        <dynamics damping="0.0" friction="0.1"/>
        <axis xyz="0 1 0"/>
    </joint>

    <joint name="base_to_lift" type="revolute">
        <parent link="base_link"/>
        <child link="full_lift"/>
        <origin xyz="-0.005 0 0.013"/>
        <limit lower="-0.8" upper="0" effort="5" velocity="10"/>
        <dynamics damping="0.0" friction="0.1"/>
        <axis xyz="0 1 0"/>
    </joint>

    <joint name="wheel_left_belt" type="fixed">
        <parent link="base_link"/>
        <child link="left_belt"/>
        <origin xyz="0.00945088 0.024 -0.0133211"/>
    </joint>

    <joint name="wheel_right_belt" type="fixed">
        <parent link="base_link"/>
        <child link="right_belt"/>
        <origin xyz="0.00945088 -0.024 -0.0133211"/>
    </joint>

    <gazebo reference="rear_right_wheel">
        <mu1>0.5</mu1>
        <mu2>0.5</mu2>
    </gazebo>
    <gazebo reference="rear_left_wheel">
        <mu1>0.5</mu1>
        <mu2>0.5</mu2>
    </gazebo>

    <gazebo reference="front_right_wheel">
        <mu1>100000</mu1>
        <mu2>100000</mu2>
    </gazebo>
    <gazebo reference="front_left_wheel">
        <mu1>100000</mu1>
        <mu2>100000</mu2>
    </gazebo>

    <gazebo reference="head">
        <kp>1000000000.0</kp>
        <kd>1000000000.0</kd>
        <mu1>10.0</mu1>
        <mu2>10.0</mu2>
        <self_collide>0</self_collide>
    </gazebo>


    <!-- Transmissions for joints -->

    <transmission name="base_to_head_trans">
        <type>transmission_interface/SimpleTransmission</type>
        <joint name="base_to_head">
            <hardwareInterface>hardware_interface/EffortJointInterface</hardwareInterface>
        </joint>
        <actuator name="base_to_headMotor">
            <hardwareInterface>hardware_interface/EffortJointInterface</hardwareInterface>
            <mechanicalReduction>1</mechanicalReduction>
        </actuator>
    </transmission>

    <transmission name="base_to_lift_trans">
        <type>transmission_interface/SimpleTransmission</type>
        <joint name="base_to_lift">
            <hardwareInterface>hardware_interface/EffortJointInterface</hardwareInterface>
        </joint>
        <actuator name="base_to_liftMotor">
            <hardwareInterface>hardware_interface/EffortJointInterface</hardwareInterface>
            <mechanicalReduction>1</mechanicalReduction>
        </actuator>
    </transmission>

    <!-- components -->
    <xacro:include filename="$(find vector_description)/urdf/vector.gazebo"/>


</robot>
