<?xml version="1.0"?>
<robot name="vector" xmlns:xacro="http://www.ros.org/wiki/xacro">

    <xacro:include filename="$(find vector_description)/urdf/common/inertia.xacro"/>

    <!-- LINKS ===========================  -->

    <!--chassis-->

    <link name="dummy">
    </link>

    <link name="imu"/>

    <link name="base_link">
        <xacro:box_inertia m="0.06" x="0.073" y="0.043" z="0.061"/>
        <visual>
            <geometry>
                <mesh filename="package://vector_description/meshes/vector_body.dae"/>
            </geometry>
        </visual>
        <collision>
            <geometry>
                <mesh filename="package://vector_description/meshes/vector_body.dae"/>
            </geometry>
        </collision>
    </link>

    <!--Front left wheel-->
    <link name="front_left_wheel">
        <xacro:cylinder_inertia m="0.01" r="0.01314" l="0.0116739"/>
        <visual>
            <geometry>
                <mesh filename="package://vector_description/meshes/flw2.dae"/>
            </geometry>
        </visual>
        <collision>
            <origin xyz="0 0 0"
                    rpy="1.57 0 0"/>
            <geometry>
                <cylinder radius="${0.026281/2.0}" length="0.0116739"/>
            </geometry>
        </collision>
    </link>

    <!--Front right wheel  -->
    <link name="front_right_wheel">
        <xacro:cylinder_inertia m="0.01" r="0.01314" l="0.0116739"/>
        <visual>
            <geometry>
                <mesh filename="package://vector_description/meshes/flw2.dae"/>
            </geometry>
        </visual>
        <collision>
            <origin xyz="0 0 0"
                    rpy="1.57 0 0"/>
            <geometry>
                <cylinder radius="${0.026281/2.0}" length="0.0116739"/>
            </geometry>
        </collision>
    </link>

    <!--Rear left wheel -->
    <link name="rear_left_wheel">
        <xacro:cylinder_inertia m="0.01" r="0.008995" l="0.0116739"/>
        <visual>
            <geometry>
                <mesh filename="package://vector_description/meshes/rlw2.dae"/>
            </geometry>
        </visual>
        <collision>
            <geometry>
                <mesh filename="package://vector_description/meshes/rlw2.dae"/>
            </geometry>
        </collision>
    </link>

    <!--Rear right wheel -->
    <link name="rear_right_wheel">
        <xacro:cylinder_inertia m="0.01" r="0.008995" l="0.0116739"/>
        <visual>
            <geometry>
                <mesh filename="package://vector_description/meshes/rlw2.dae"/>
            </geometry>
        </visual>
        <collision>
            <geometry>
                <mesh filename="package://vector_description/meshes/rlw2.dae"/>
            </geometry>
        </collision>
    </link>

    <!-- Head -->
    <link name="head">
        <xacro:box_inertia m="0.01" x="0.036" y="0.038" z="0.041"/>
        <visual>
            <geometry>
                <mesh filename="package://vector_description/meshes/vector_head.dae"/>
            </geometry>
        </visual>
        <collision>
            <geometry>
                <mesh filename="package://vector_description/meshes/vector_head.dae"/>
            </geometry>
        </collision>
    </link>

    <!-- lifter -->
    <link name="full_lift">
        <xacro:box_inertia m="0.01" x="0.081" y="0.058" z="0.050"/>
        <visual>
            <geometry>
                <mesh filename="package://vector_description/meshes/vector_lift.dae"/>
            </geometry>
        </visual>
        <collision>
            <geometry>
                <mesh filename="package://vector_description/meshes/vector_lift.dae"/>
            </geometry>
        </collision>
    </link>

    <!-- Belts -->
    <link name="left_belt">
        <inertial>
            <mass value="0.0001"/>
            <inertia ixx="0.000001" ixy="0" ixz="0" iyy="0.000001" iyz="0" izz="0.0000001"/>
        </inertial>
        <visual>
            <geometry>
                <mesh filename="package://vector_description/meshes/cozmo_belt.dae"/>
            </geometry>
        </visual>
    </link>

    <link name="right_belt">
        <inertial>
            <mass value="0.0001"/>
            <inertia ixx="0.000001" ixy="0" ixz="0" iyy="0.000001" iyz="0" izz="0.0000001"/>
        </inertial>
        <visual>
            <geometry>
                <mesh filename="package://vector_description/meshes/cozmo_belt.dae"/>
            </geometry>
        </visual>
    </link>

    <!-- sensors links -->
    <link name="camera_link"/>
    <link name="drop_ir_fl"/>
    <link name="drop_ir_fr"/>
    <link name="drop_ir_rl"/>
    <link name="drop_ir_rr"/>


    <!-- JOINTS ====================================-->
    <joint name="dummy_joint" type="fixed">
        <parent link="dummy"/>
        <child link="base_link"/>
    </joint>

    <joint name="base_to_flw" type="continuous">
        <parent link="base_link"/>
        <child link="front_left_wheel"/>
        <origin xyz="0.03 0.024 -0.012"/>
        <axis xyz="0 1 0"/>
    </joint>

    <joint name="base_to_frw" type="continuous">
        <parent link="base_link"/>
        <child link="front_right_wheel"/>
        <origin xyz="0.03 -0.024 -0.012"/>
        <axis xyz="0 1 0"/>
    </joint>

    <joint name="base_to_rlw" type="continuous">
        <parent link="base_link"/>
        <child link="rear_left_wheel"/>
        <origin xyz="-0.017 0.024 -0.0151707"/>
        <axis xyz="0 1 0"/>
    </joint>

    <joint name="base_to_rrw" type="continuous">
        <parent link="base_link"/>
        <child link="rear_right_wheel"/>
        <origin xyz="-0.017 -0.024 -0.0151707"/>
        <axis xyz="0 1 0"/>
    </joint>


    <joint name="base_to_head" type="revolute">
        <parent link="base_link"/>
        <child link="head"/>
        <origin xyz="0.0174507 0 0.022003"/>
        <limit lower="-0.52" upper="0.17" effort="100" velocity="10"/>
        <!-- Dampning break the model, keep it 0.0 -->
        <dynamics damping="0.0" friction="0.1"/>
        <axis xyz="0 1 0"/>
    </joint>

    <joint name="base_to_lift" type="revolute">
        <parent link="base_link"/>
        <child link="full_lift"/>
        <origin xyz="-0.005 0 0.013"/>
        <limit lower="-0.8" upper="0" effort="5" velocity="10"/>
        <dynamics damping="0.0" friction="0.1"/>
        <axis xyz="0 1 0"/>
    </joint>

    <joint name="wheel_left_belt" type="fixed">
        <parent link="base_link"/>
        <child link="left_belt"/>
        <origin xyz="0.00945088 0.024 -0.0133211"/>
    </joint>

    <joint name="wheel_right_belt" type="fixed">
        <parent link="base_link"/>
        <child link="right_belt"/>
        <origin xyz="0.00945088 -0.024 -0.0133211"/>
    </joint>

    <joint name="head_camera_joint" type="fixed">
        <parent link="head"/>
        <child link="camera_link"/>
        <origin xyz="0.020813 0 -0.0071471" rpy="0 0 0"/>
    </joint>

    <joint name="drop_ir_fl_joint" type="fixed">
        <parent link="base_link"/>
        <child link="drop_ir_fl"/>
        <origin xyz="0.0351028 0.01 -0.0213898" rpy="0 1.57 0"/>
    </joint>

    <joint name="drop_ir_fr_joint" type="fixed">
        <parent link="base_link"/>
        <child link="drop_ir_fr"/>
        <origin xyz="0.0351028 -0.01 -0.0213898" rpy="0 1.57 0"/>
    </joint>

    <joint name="drop_ir_rl_joint" type="fixed">
        <parent link="base_link"/>
        <child link="drop_ir_rl"/>
        <origin xyz="-0.02 0.01 -0.0213898" rpy="0 1.57 0"/>
    </joint>

    <joint name="drop_ir_rr_joint" type="fixed">
        <parent link="base_link"/>
        <child link="drop_ir_rr"/>
        <origin xyz="-0.02 -0.01 -0.0213898" rpy="0 1.57 0"/>
    </joint>

    <joint name="imu_joint" type="fixed">
        <parent link="head"/>
        <child link="imu"/>
        <origin xyz="0.0 0 0.0" rpy="0 0 0"/>
    </joint>


    <gazebo reference="rear_right_wheel">
        <mu1>0.5</mu1>
        <mu2>0.5</mu2>
    </gazebo>
    <gazebo reference="rear_left_wheel">
        <mu1>0.5</mu1>
        <mu2>0.5</mu2>
    </gazebo>


    <gazebo reference="front_right_wheel">
        <mu1>100000</mu1>
        <mu2>100000</mu2>
    </gazebo>
    <gazebo reference="front_left_wheel">
        <mu1>100000</mu1>
        <mu2>100000</mu2>
    </gazebo>

    <gazebo reference="head">
        <kp>1000000000.0</kp>
        <kd>1000000000.0</kd>
        <mu1>10.0</mu1>
        <mu2>10.0</mu2>
        <self_collide>0</self_collide>
    </gazebo>


    <!-- Transmissions for joints -->

    <transmission name="base_to_head_trans">
        <type>transmission_interface/SimpleTransmission</type>
        <joint name="base_to_head">
            <hardwareInterface>hardware_interface/EffortJointInterface</hardwareInterface>
        </joint>
        <actuator name="base_to_headMotor">
            <hardwareInterface>hardware_interface/EffortJointInterface</hardwareInterface>
            <mechanicalReduction>1</mechanicalReduction>
        </actuator>
    </transmission>

    <transmission name="base_to_lift_trans">
        <type>transmission_interface/SimpleTransmission</type>
        <joint name="base_to_lift">
            <hardwareInterface>hardware_interface/EffortJointInterface</hardwareInterface>
        </joint>
        <actuator name="base_to_liftMotor">
            <hardwareInterface>hardware_interface/EffortJointInterface</hardwareInterface>
            <mechanicalReduction>1</mechanicalReduction>
        </actuator>
    </transmission>

    <!-- ROS Control plugin for Gazebo -->
    <gazebo>
        <plugin name="gazebo_ros_control" filename="libgazebo_ros_control.so">
            <robotNamespace>/vector</robotNamespace>
            <legacyModeNS>true</legacyModeNS>
        </plugin>
    </gazebo>


    <gazebo>
        <plugin name="skid_steer_drive_controller" filename="libgazebo_ros_skid_steer_drive.so">
            <updateRate>25.0</updateRate>
            <robotNamespace>/</robotNamespace>
            <leftFrontJoint>base_to_flw</leftFrontJoint>
            <rightFrontJoint>base_to_frw</rightFrontJoint>
            <leftRearJoint>base_to_rlw</leftRearJoint>
            <rightRearJoint>base_to_rrw</rightRearJoint>
            <wheelSeparation>0.048</wheelSeparation>
            <wheelDiameter>0.026281</wheelDiameter>
            <robotBaseFrame>base_link</robotBaseFrame>
            <torque>20</torque>
            <topicName>cmd_vel</topicName>
            <commandTopic>cmd_vel</commandTopic>
            <odometryTopic>odom</odometryTopic>
            <odometryFrame>odom</odometryFrame>
            <broadcastTF>1</broadcastTF>
        </plugin>
    </gazebo>

    <gazebo reference="camera_link">
        <sensor type="camera" name="cozmo_camera">
            <update_rate>10.0</update_rate>
            <camera name="headcamera">
                <horizontal_fov>1.3962634</horizontal_fov>
                <image>
                    <width>1280</width>
                    <height>720</height>
                    <format>R8G8B8</format>
                </image>
                <clip>
                    <near>0.01</near>
                    <far>100</far>
                </clip>
                <noise>
                    <type>gaussian</type>

                    <mean>0.0</mean>
                    <stddev>0.007</stddev>
                </noise>
            </camera>
            <plugin name="camera_controller" filename="libgazebo_ros_camera.so">
                <alwaysOn>true</alwaysOn>
                <updateRate>25.0</updateRate>
                <cameraName>camera</cameraName>
                <imageTopicName>image</imageTopicName>
                <cameraInfoTopicName>camera_info</cameraInfoTopicName>
                <frameName>camera_link</frameName>
                <hackBaseline>0.07</hackBaseline>
                <distortionK1>0.0</distortionK1>
                <distortionK2>0.0</distortionK2>
                <distortionK3>0.0</distortionK3>
                <distortionT1>0.0</distortionT1>
                <distortionT2>0.0</distortionT2>
            </plugin>
        </sensor>
    </gazebo>


    <gazebo reference="drop_ir_fl">
        <sensor type="ray" name="TeraRanger">
            <pose>0 0 0 0 0 0</pose>
            <visualize>true</visualize>
            <update_rate>50</update_rate>
            <ray>
                <scan>
                    <horizontal>
                        <samples>10</samples>
                        <resolution>1</resolution>
                        <min_angle>-0.14835</min_angle>
                        <max_angle>0.14835</max_angle>
                    </horizontal>
                    <vertical>
                        <samples>10</samples>
                        <resolution>1</resolution>
                        <min_angle>-0.14835</min_angle>
                        <max_angle>0.14835</max_angle>
                    </vertical>
                </scan>
                <range>
                    <min>0.01</min>
                    <max>2</max>
                    <resolution>0.02</resolution>
                </range>
            </ray>
            <plugin filename="libgazebo_ros_range.so" name="gazebo_ros_range">
                <gaussianNoise>0.005</gaussianNoise>
                <alwaysOn>true</alwaysOn>
                <updateRate>50</updateRate>
                <topicName>drop_sensor_fl</topicName>
                <frameName>drop_ir_fl</frameName>
                <radiation>INFRARED</radiation>
                <fov>0.2967</fov>
            </plugin>
        </sensor>
    </gazebo>


    <gazebo reference="drop_ir_fr">
        <sensor type="ray" name="TeraRanger">
            <pose>0 0 0 0 0 0</pose>
            <visualize>true</visualize>
            <update_rate>50</update_rate>
            <ray>
                <scan>
                    <horizontal>
                        <samples>10</samples>
                        <resolution>1</resolution>
                        <min_angle>-0.14835</min_angle>
                        <max_angle>0.14835</max_angle>
                    </horizontal>
                    <vertical>
                        <samples>10</samples>
                        <resolution>1</resolution>
                        <min_angle>-0.14835</min_angle>
                        <max_angle>0.14835</max_angle>
                    </vertical>
                </scan>
                <range>
                    <min>0.01</min>
                    <max>2</max>
                    <resolution>0.02</resolution>
                </range>
            </ray>
            <plugin filename="libgazebo_ros_range.so" name="gazebo_ros_range">
                <gaussianNoise>0.005</gaussianNoise>
                <alwaysOn>true</alwaysOn>
                <updateRate>50</updateRate>
                <topicName>drop_sensor_fr</topicName>
                <frameName>drop_ir_fr</frameName>
                <radiation>INFRARED</radiation>
                <fov>0.2967</fov>
            </plugin>
        </sensor>
    </gazebo>


    <gazebo reference="drop_ir_rl">
        <sensor type="ray" name="TeraRanger">
            <pose>0 0 0 0 0 0</pose>
            <visualize>true</visualize>
            <update_rate>50</update_rate>
            <ray>
                <scan>
                    <horizontal>
                        <samples>10</samples>
                        <resolution>1</resolution>
                        <min_angle>-0.14835</min_angle>
                        <max_angle>0.14835</max_angle>
                    </horizontal>
                    <vertical>
                        <samples>10</samples>
                        <resolution>1</resolution>
                        <min_angle>-0.14835</min_angle>
                        <max_angle>0.14835</max_angle>
                    </vertical>
                </scan>
                <range>
                    <min>0.01</min>
                    <max>2</max>
                    <resolution>0.02</resolution>
                </range>
            </ray>
            <plugin filename="libgazebo_ros_range.so" name="gazebo_ros_range">
                <gaussianNoise>0.005</gaussianNoise>
                <alwaysOn>true</alwaysOn>
                <updateRate>50</updateRate>
                <topicName>drop_sensor_rl</topicName>
                <frameName>drop_ir_rl</frameName>
                <radiation>INFRARED</radiation>
                <fov>0.2967</fov>
            </plugin>
        </sensor>
    </gazebo>


    <gazebo reference="drop_ir_rr">
        <sensor type="ray" name="TeraRanger">
            <pose>0 0 0 0 0 0</pose>
            <visualize>true</visualize>
            <update_rate>50</update_rate>
            <ray>
                <scan>
                    <horizontal>
                        <samples>10</samples>
                        <resolution>1</resolution>
                        <min_angle>-0.14835</min_angle>
                        <max_angle>0.14835</max_angle>
                    </horizontal>
                    <vertical>
                        <samples>10</samples>
                        <resolution>1</resolution>
                        <min_angle>-0.14835</min_angle>
                        <max_angle>0.14835</max_angle>
                    </vertical>
                </scan>
                <range>
                    <min>0.01</min>
                    <max>2</max>
                    <resolution>0.02</resolution>
                </range>
            </ray>
            <plugin filename="libgazebo_ros_range.so" name="gazebo_ros_range">
                <gaussianNoise>0.005</gaussianNoise>
                <alwaysOn>true</alwaysOn>
                <updateRate>50</updateRate>
                <topicName>drop_sensor_rr</topicName>
                <frameName>drop_ir_rr</frameName>
                <radiation>INFRARED</radiation>
                <fov>0.2967</fov>
            </plugin>
        </sensor>
    </gazebo>

    <!-- components -->
    <xacro:include filename="$(find vector_description)/urdf/vector.gazebo"/>


</robot>
