<?xml version="1.0"?>
<robot xmlns:xacro="http://www.ros.org/wiki/xacro">

    <macro name="wheel" params="link_name *origin radius filename">
        <link name="${link_name}">
            <visual>
                <material name="black"/>
                <origin rpy="0 0 0" xyz="0 0 0"/>
                <geometry>
                    <mesh filename="${filename}"/>
                </geometry>
            </visual>
            <collision>
                <origin rpy="0 0 0" xyz="0 0 0"/>
                <geometry>
                    <cylinder radius="${radius}" length="0.0116739"/>
                </geometry>
            </collision>
            <inertial>
                <origin rpy="0 0 0" xyz="0 0 0"/>
                <geometry>
                    <cylinder radius="${radius}" length="0.0116739"/>
                </geometry>
                <mass value="0.01"/>
                <xacro:cylinder_inertia m="0.01" r="${radius}" l="0.01167"/>
            </inertial>
        </link>
        <joint name="${link_name}_joint" type="continuous">
            <parent link="base_link"/>
            <child link="${link_name}"/>
            <xacro:insert_block name="origin"/>
            <axis xyz="0 1 0"/>
        </joint>
    </macro>
</robot>